<?xml version="1.0" ?>
<!-- =================================================================================== -->
<!-- |    This document was autogenerated by xacro                                     | -->
<!-- |    EDITING THIS FILE BY HAND IS NOT RECOMMENDED                                 | -->
<!-- =================================================================================== -->
<robot name="fr3" xmlns:xacro="http://www.ros.org/wiki/xacro">
    <link name="fr3_link_stationary">
        <visual>
            <geometry>
                <mesh filename="package://fr3_description/meshes/visual/stationary_platform.dae" />
            </geometry>
        </visual>
        <collision>
            <geometry>
                <mesh filename="package://fr3_description/meshes/collision/stationary_platform.stl" />
            </geometry>
        </collision>
        <inertial>
            <origin rpy="0 0 0" xyz="-0.0172 0.0004 0.0745"/>
            <!-- Exact inertials for stationary joint shouldnt matter that much for now -->
            <mass value="5.500"/> 
            <inertia ixx="0.009" ixy="0.0" ixz="0.002" iyy="0.0115" iyz="0.0" izz="0.0085"/>
        </inertial>
    </link>
    <link name="fr3_link0">
        <visual>
            <geometry>
                <mesh filename="package://fr3_description/meshes/visual/moving_platform.dae" />
            </geometry>
        </visual>
        <collision>
            <geometry>
                <mesh filename="package://fr3_description/meshes/collision/moving_platform.stl" />
            </geometry>
        </collision>
        <inertial>
            <origin rpy="0 0 0" xyz="-0.0172 0.0004 0.0745"/>
            <!-- TODO: Update this with the mass of the moving platform attatched -->
            <mass value="2.3966"/>
            <inertia ixx="0.009" ixy="0.0" ixz="0.002" iyy="0.0115" iyz="0.0" izz="0.0085"/>
        </inertial>
    </link>
    <joint name="fr3_joint_linear" type="prismatic">
        <parent link="fr3_link_stationary"/>
        <child link="fr3_link0"/>
        <origin rpy="0 0 0" xyz="0.051 0.1202 0.0764"/>
        <axis xyz="0 1 0"/>
        <!-- Will need to update with actual params later -->
        <limit effort="200.0" lower="0.0" upper="0.72" velocity="0.75"/>
		<dynamics damping="0.01" friction="0.1"/>
	</joint>
    <link name="fr3_link1">
        <visual>
            <geometry>
                <mesh filename="package://fr3_description/meshes/visual/link1.dae" />
            </geometry>
        </visual>
        <collision>
            <geometry>
                <mesh filename="package://fr3_description/meshes/collision/link1.stl" />
            </geometry>
        </collision>
        <inertial>
            <origin rpy="0 0 0" xyz="0.0000004128 -0.0181251324 -0.0386035970"/>
            <mass value="2.9274653454"/>
            <inertia ixx="0.023927316485107913" ixy="1.3317903455714081e-05" ixz="-0.00011404774918616684" iyy="0.0224821613275756" iyz="-0.0019950320628240115" izz="0.006350098258530016"/>
        </inertial>
    </link>
    <joint name="fr3_joint1" type="revolute">
        <origin rpy="0 0 0" xyz="0 0 0.333" />
        <parent link="fr3_link0" />
        <child link="fr3_link1" />
        <axis xyz="0 0 1" />
        <limit effort="87" lower="-2.9671" upper="2.9671" velocity="2.3925" />
    	<dynamics damping="0.003" friction="0.1"/>
	</joint>
    <link name="fr3_link2">
        <visual>
            <geometry>
                <mesh filename="package://fr3_description/meshes/visual/link2.dae" />
            </geometry>
        </visual>
        <collision>
            <geometry>
                <mesh filename="package://fr3_description/meshes/collision/link2.stl" />
            </geometry>
        </collision>
        <inertial>
            <origin rpy="0 0 0" xyz="0.0031828864 -0.0743221644 0.0088146084"/>
            <mass value="2.9355370338"/>
            <inertia ixx="0.041938946257609425" ixy="0.00020257331521090626" ixz="0.004077784227179924" iyy="0.02514514885014724" iyz="-0.0042252158006570156" izz="0.06170214472888839"/>
        </inertial>
    </link>
    <joint name="fr3_joint2" type="revolute">
        <origin rpy="-1.57079632679 0 0" xyz="0 0 0" />
        <parent link="fr3_link1" />
        <child link="fr3_link2" />
        <axis xyz="0 0 1" />
        <limit effort="87" lower="-1.8326" upper="1.8326" velocity="2.3925" />
    	<dynamics damping="0.003" friction="0.1"/>
	</joint>
    <link name="fr3_link3">
        <visual>
            <geometry>
                <mesh filename="package://fr3_description/meshes/visual/link3.dae" />
            </geometry>
        </visual>
        <collision>
            <geometry>
                <mesh filename="package://fr3_description/meshes/collision/link3.stl" />
            </geometry>
        </collision>
        <inertial>
            <origin rpy="0 0 0" xyz="0.0407015686 -0.0048200565 -0.0289730823"/>
            <mass value="2.2449013699"/>
            <inertia ixx="0.02410142547240885" ixy="0.002404694559042109" ixz="-0.002856269270114313" iyy="0.01974053266708178" iyz="-0.002104212683891874" izz="0.019044494482244823"/>
        </inertial>
    </link>
    <joint name="fr3_joint3" type="revolute">
        <origin rpy="1.57079632679 0 0" xyz="0 -0.316 0" />
        <parent link="fr3_link2" />
        <child link="fr3_link3" />
        <axis xyz="0 0 1" />
        <limit effort="87" lower="-2.9671" upper="2.9671" velocity="2.3925" />
    	<dynamics damping="0.003" friction="0.1"/>
	</joint>
    <link name="fr3_link4">
        <visual>
            <geometry>
                <mesh filename="package://fr3_description/meshes/visual/link4.dae" />
            </geometry>
        </visual>
        <collision>
            <geometry>
                <mesh filename="package://fr3_description/meshes/collision/link4.stl" />
            </geometry>
        </collision>
        <inertial>
            <origin rpy="0 0 0" xyz="-0.0459100965 0.0630492960 -0.0085187868"/>
            <mass value="2.6155955791"/>
            <inertia ixx="0.03452998321913202" ixy="0.01322552265982813" ixz="0.01015142998484113" iyy="0.028881621933049058" iyz="-0.0009762833870704552" izz="0.04125471171146641"/>
        </inertial>
    </link>
    <joint name="fr3_joint4" type="revolute">
        <origin rpy="1.57079632679 0 0" xyz="0.0825 0 0" />
        <parent link="fr3_link3" />
        <child link="fr3_link4" />
        <axis xyz="0 0 1" />
        <limit effort="87" lower="-3.1416" upper="0.0873" velocity="2.3925" />
    	<dynamics damping="0.003" friction="0.1"/>
	</joint>
    <link name="fr3_link5">
        <visual>
            <geometry>
                <mesh filename="package://fr3_description/meshes/visual/link5.dae" />
            </geometry>
        </visual>
        <collision>
            <geometry>
                <mesh filename="package://fr3_description/meshes/collision/link5.stl" />
            </geometry>
        </collision>
        <inertial>
            <origin rpy="0 0 0" xyz="-0.0016039605 0.0292536262 -0.0972965990"/>
            <mass value="2.3271207594"/>
            <inertia ixx="0.051610278463662895" ixy="-0.005715173387783472" ixz="-0.0035673167625872135" iyy="0.04787729713371481" iyz="0.010673985108535986" izz="0.016423625579357254"/>
        </inertial>
    </link>
    <joint name="fr3_joint5" type="revolute">
        <origin rpy="-1.57079632679 0 0" xyz="-0.0825 0.384 0" />
        <parent link="fr3_link4" />
        <child link="fr3_link5" />
        <axis xyz="0 0 1" />
        <limit effort="12" lower="-2.9671" upper="2.9671" velocity="2.8710" />
    	<dynamics damping="0.003" friction="0.1"/>
	</joint>
    <link name="fr3_link6">
        <visual>
            <geometry>
                <mesh filename="package://fr3_description/meshes/visual/link6.dae" />
            </geometry>
        </visual>
        <collision>
            <geometry>
                <mesh filename="package://fr3_description/meshes/collision/link6.stl" />
            </geometry>
        </collision>
        <inertial>
            <origin rpy="0 0 0" xyz="0.0597131221 -0.0410294666 -0.0101692726"/>
            <mass value="1.8170376524"/>
            <inertia ixx="0.005412333594383447" ixy="0.006193456360285834" ixz="0.0014219289306117652" iyy="0.014058329545509979" iyz="-0.0013140753741120031" izz="0.016080817924212554"/>
        </inertial>
    </link>
    <joint name="fr3_joint6" type="revolute">
        <origin rpy="1.57079632679 0 0" xyz="0 0 0" />
        <parent link="fr3_link5" />
        <child link="fr3_link6" />
        <axis xyz="0 0 1" />
        <limit effort="12" lower="-0.0873" upper="3.8223" velocity="2.8710" />
    	<dynamics damping="0.003" friction="0.1"/>
	</joint>
    <link name="fr3_link7">
        <visual>
            <geometry>
                <mesh filename="package://fr3_description/meshes/visual/link7.dae" />
            </geometry>
        </visual>
        <collision>
            <geometry>
                <mesh filename="package://fr3_description/meshes/collision/link7.stl" />
            </geometry>
        </collision>
        <inertial>
            <origin rpy="0 0 0" xyz="0.0045225817 0.0086261921 -0.0161633251"/>
            <mass value="0.6271432862"/>
            <inertia ixx="0.00021092389150104718" ixy="-2.433299114461931e-05" ixz="4.564480393778983e-05" iyy="0.00017718568002411474" iyz="8.744070223226438e-05" izz="5.993190599659971e-05"/>
        </inertial>
    </link>
    <joint name="fr3_joint7" type="revolute">
        <origin rpy="1.57079632679 0 0" xyz="0.088 0 0" />
        <parent link="fr3_link6" />
        <child link="fr3_link7" />
        <axis xyz="0 0 1" />
        <limit effort="12" lower="-2.9671" upper="2.9671" velocity="2.8710" />
    	<dynamics damping="0.003" friction="0.1"/>
	</joint>
    <link name="fr3_link8" />
    <joint name="fr3_joint8" type="fixed">
        <origin rpy="0 0 0" xyz="0 0 0.107" />
        <parent link="fr3_link7" />
        <child link="fr3_link8" />
        <axis xyz="0 0 0" />
    </joint>
    <joint name="fr3_hand_joint" type="fixed">
        <parent link="fr3_link8" />
        <child link="fr3_hand" />
        <origin rpy="0 0 -0.785398163397" xyz="0 0 0" />
    </joint>
    <link name="fr3_hand">
        <visual>
            <geometry>
                <mesh filename="package://fr3_description/meshes/visual/hand.dae" />
            </geometry>
        </visual>
        <collision>
            <geometry>
                <mesh filename="package://fr3_description/meshes/collision/hand.stl" />
            </geometry>
        </collision>
        <inertial>
            <origin rpy="0 0 0" xyz="-0.0000376 0.0119128 0.0207260"/>
            <mass value="0.6544"/>
            <inertia ixx="0.00186" ixy="0.0" ixz="0.0" iyy="0.0003" iyz="-2e-05" izz="0.00174"/>
        </inertial>
    </link>
    <link name="fr3_leftfinger">
        <visual>
            <geometry>
                <mesh filename="package://fr3_description/meshes/visual/finger.dae" />
            </geometry>
        </visual>
        <collision>
            <geometry>
                <mesh filename="package://fr3_description/meshes/collision/finger.stl" />
            </geometry>
        </collision>
        <inertial>
            <origin rpy="0 0 0" xyz="0 0.0152850 0.0219675"/>
            <mass value="0.0291"/>
            <inertia ixx="8.49e-06" ixy="0.0" ixz="0.0" iyy="8.53e-06" iyz="-1.06e-06" izz="1.77e-06"/>
        </inertial>
    </link>
    <link name="fr3_rightfinger">
        <visual>
            <origin rpy="0 0 3.14159265359" xyz="0 0 0" />
            <geometry>
                <mesh filename="package://fr3_description/meshes/visual/finger.dae" />
            </geometry>
        </visual>
        <collision>
            <origin rpy="0 0 3.14159265359" xyz="0 0 0" />
            <geometry>
                <mesh filename="package://fr3_description/meshes/collision/finger.stl" />
            </geometry>
        </collision>
        <inertial>
            <origin rpy="0 0 0" xyz="0 0.0152850 0.0219675"/>
            <mass value="0.0291"/>
            <inertia ixx="8.49e-06" ixy="0.0" ixz="0.0" iyy="8.53e-06" iyz="-1.06e-06" izz="1.77e-06"/>
        </inertial>
    </link>
    <joint name="fr3_finger_joint1" type="prismatic">
        <parent link="fr3_hand" />
        <child link="fr3_leftfinger" />
        <origin rpy="0 0 0" xyz="0 0 0.0584" />
        <axis xyz="0 1 0" />
        <limit effort="20" lower="0.0" upper="0.04" velocity="0.2" />
        <dynamics damping="0.05"/>
    </joint>
    <joint name="fr3_finger_joint2" type="prismatic">
        <parent link="fr3_hand" />
        <child link="fr3_rightfinger" />
        <origin rpy="0 0 0" xyz="0 0 0.0584" />
        <axis xyz="0 -1 0" />
        <limit effort="20" lower="0.0" upper="0.04" velocity="0.2" />
        <dynamics damping="0.05"/>
        <mimic joint="fr3_finger_joint1" />
    </joint>
</robot>
